Workbook

Sheet HBM Channels
A1: config_label | B1: kind | C1: engine_shape | D1: engines | E1: lanes_total | F1: weights_ch | G1: indices_ch | H1: activation_ch | I1: output_ch | J1: total_ch | K1: unused_ch | L1: uses_second_stack | M1: saved_by_sharing | N1: shared_twin_of | O1: engine_dsp | P1: build_dsp | Q1: dsp_pct | R1: dsp_source | S1: clock_mhz | T1: status
A2: 4x4 (6 ch) | B2: single engine | C2: 4x4 | D2: 1 | E2: 16 | F2: 2 | G2: 1 | H2: 2 | I2: 1 | J2: 6 | K2: 26 | L2: no | M2: 0 | O2: 128 | P2: 132 | Q2: 1.46 | R2: measured (routed utilization report) | S2: 400 | T2: built and measured
A3: 8x4 (10 ch) | B3: single engine | C3: 8x4 | D3: 1 | E3: 32 | F3: 4 | G3: 2 | H3: 2 | I3: 2 | J3: 10 | K3: 22 | L3: no | M3: 0 | O3: 256 | P3: 260 | Q3: 2.88 | R3: measured (routed utilization report) | S3: 375 | T3: built and measured
A4: 2 x 4x4 (12 ch) | B4: multi-tenant, own vector channels | C4: 4x4 | D4: 2 | E4: 32 | F4: 4 | G4: 2 | H4: 4 | I4: 2 | J4: 12 | K4: 20 | L4: no | M4: 0 | O4: 256 | P4: 260 | Q4: 2.88 | R4: measured (routed utilization report) | S4: 394 | T4: built and measured
A5: 16x3 (13 ch) | B5: single engine | C5: 16x3 | D5: 1 | E5: 48 | F5: 6 | G5: 2 | H5: 2 | I5: 3 | J5: 13 | K5: 19 | L5: no | M5: 0 | O5: 384 | P5: 388 | Q5: 4.3 | R5: measured (routed utilization report) | S5: 350 | T5: built and measured
A6: 3 x 4x4 shared (14 ch) | B6: multi-tenant, shared vector channels | C6: 4x4 | D6: 3 | E6: 48 | F6: 6 | G6: 3 | H6: 2 | I6: 3 | J6: 14 | K6: 18 | L6: no | M6: 4 | N6: 3 x 4x4 (18 ch) | O6: 384 | P6: 388 | Q6: 4.3 | R6: formula: 8 per lane x lanes + 4 platform (not built yet) | T6: to build
A7: 3 x 4x4 (18 ch) | B7: multi-tenant, own vector channels | C7: 4x4 | D7: 3 | E7: 48 | F7: 6 | G7: 3 | H7: 6 | I7: 3 | J7: 18 | K7: 14 | L7: yes | M7: 0 | O7: 384 | P7: 388 | Q7: 4.3 | R7: measured (routed utilization report) | S7: 399 | T7: built and measured
A8: 8x8 (17 ch) | B8: single engine | C8: 8x8 | D8: 1 | E8: 64 | F8: 8 | G8: 3 | H8: 2 | I8: 4 | J8: 17 | K8: 15 | L8: yes | M8: 0 | O8: 512 | P8: 516 | Q8: 5.72 | R8: measured (routed utilization report) | S8: 325 | T8: built and measured
A9: 2 x 8x4 (20 ch) | B9: multi-tenant, own vector channels | C9: 8x4 | D9: 2 | E9: 64 | F9: 8 | G9: 4 | H9: 4 | I9: 4 | J9: 20 | K9: 12 | L9: yes | M9: 0 | O9: 512 | P9: 516 | Q9: 5.72 | R9: measured (routed utilization report) | S9: 361 | T9: built and measured
A10: 4 x 4x4 (24 ch) | B10: multi-tenant, own vector channels | C10: 4x4 | D10: 4 | E10: 64 | F10: 8 | G10: 4 | H10: 8 | I10: 4 | J10: 24 | K10: 8 | L10: yes | M10: 0 | O10: 512 | P10: 516 | Q10: 5.72 | R10: measured (routed utilization report) | S10: 374 | T10: built and measured
A11: 5 x 4x4 (30 ch) | B11: multi-tenant, own vector channels | C11: 4x4 | D11: 5 | E11: 80 | F11: 10 | G11: 5 | H11: 10 | I11: 5 | J11: 30 | K11: 2 | L11: yes | M11: 0 | O11: 640 | P11: 644 | Q11: 7.14 | R11: measured (routed utilization report) | S11: 329 | T11: built and measured
A12: 4x24 (24 ch) | B12: single engine | C12: 4x24 | D12: 1 | E12: 96 | F12: 12 | G12: 4 | H12: 2 | I12: 6 | J12: 24 | K12: 8 | L12: yes | M12: 0 | O12: 768 | P12: 772 | Q12: 8.55 | R12: measured (routed utilization report) | S12: 300 | T12: built and measured
A13: 2 x 16x3 shared (24 ch) | B13: multi-tenant, shared vector channels | C13: 16x3 | D13: 2 | E13: 96 | F13: 12 | G13: 4 | H13: 2 | I13: 6 | J13: 24 | K13: 8 | L13: yes | M13: 2 | N13: 2 x 16x3 (26 ch) | O13: 768 | P13: 772 | Q13: 8.55 | R13: formula: 8 per lane x lanes + 4 platform (not built yet) | T13: to build
A14: 6 x 4x4 shared (26 ch) | B14: multi-tenant, shared vector channels | C14: 4x4 | D14: 6 | E14: 96 | F14: 12 | G14: 6 | H14: 2 | I14: 6 | J14: 26 | K14: 6 | L14: yes | M14: 10 | O14: 768 | P14: 772 | Q14: 8.55 | R14: formula: 8 per lane x lanes + 4 platform (not built yet) | T14: to build
A15: 3 x 8x4 shared (26 ch) | B15: multi-tenant, shared vector channels | C15: 8x4 | D15: 3 | E15: 96 | F15: 12 | G15: 6 | H15: 2 | I15: 6 | J15: 26 | K15: 6 | L15: yes | M15: 4 | N15: 3 x 8x4 (30 ch) | O15: 768 | P15: 772 | Q15: 8.55 | R15: formula: 8 per lane x lanes + 4 platform (not built yet) | T15: to build
A16: 2 x 16x3 (26 ch) | B16: multi-tenant, own vector channels | C16: 16x3 | D16: 2 | E16: 96 | F16: 12 | G16: 4 | H16: 4 | I16: 6 | J16: 26 | K16: 6 | L16: yes | M16: 0 | O16: 768 | P16: 772 | Q16: 8.55 | R16: measured (routed utilization report) | S16: 341 | T16: built and measured
A17: 3 x 8x4 (30 ch) | B17: multi-tenant, own vector channels | C17: 8x4 | D17: 3 | E17: 96 | F17: 12 | G17: 6 | H17: 6 | I17: 6 | J17: 30 | K17: 2 | L17: yes | M17: 0 | O17: 768 | P17: 772 | Q17: 8.55 | R17: measured (routed utilization report) | S17: 354 | T17: built and measured
A18: 7 x 4x4 shared (30 ch) | B18: multi-tenant, shared vector channels | C18: 4x4 | D18: 7 | E18: 112 | F18: 14 | G18: 7 | H18: 2 | I18: 7 | J18: 30 | K18: 2 | L18: yes | M18: 12 | O18: 896 | P18: 900 | Q18: 9.97 | R18: formula: 8 per lane x lanes + 4 platform (not built yet) | T18: to build
A19: 4x32 (32 ch) | B19: single engine | C19: 4x32 | D19: 1 | E19: 128 | F19: 16 | G19: 6 | H19: 2 | I19: 8 | J19: 32 | K19: 0 | L19: yes | M19: 0 | O19: 1024 | P19: 1028 | Q19: 11.39 | R19: measured (routed utilization report) | S19: 250 | T19: built and measured
A20: 2 x 8x8 shared (32 ch) | B20: multi-tenant, shared vector channels | C20: 8x8 | D20: 2 | E20: 128 | F20: 16 | G20: 6 | H20: 2 | I20: 8 | J20: 32 | K20: 0 | L20: yes | M20: 2 | O20: 1024 | P20: 1028 | Q20: 11.39 | R20: formula: 8 per lane x lanes + 4 platform (not built yet) | T20: to build

Sheet Workload
A1: config_label | B1: engine_ms_single | C1: overhead_ms_single | D1: engine_ms_multi | E1: overhead_ms_multi | F1: static_mJ_single | G1: dynamic_mJ_single | H1: static_mJ_multi | I1: dynamic_mJ_multi | J1: wall_gmac_s_single | K1: wall_gmac_s_multi | L1: engine_gmac_s_single | M1: engine_gmac_s_multi | N1: nj_per_mac_single | O1: nj_per_mac_multi | P1: kind | Q1: configuration | R1: engine_shape | S1: tenants | T1: hbm_channels | U1: lanes_total | V1: clock_mhz | W1: matrices | X1: useful_macs | Y1: padded_macs | Z1: padding_pct | AA1: calcs_per_tenant | AB1: efficiency_pct | AC1: predicted_us | AD1: engine_us | AE1: active_sum_us | AF1: wall_pass_us | AG1: overhead_us | AH1: overhead_pct | AI1: wall_gmac_s | AJ1: engine_gmac_s | AK1: board_load_W | AL1: board_idle_W | AM1: dynamic_W | AN1: energy_pass_mJ | AO1: static_mJ | AP1: dynamic_mJ | AQ1: nj_per_mac_wall | AR1: fullrate_load_W | AS1: nj_per_mac_launch_free | AT1: finish_balance | AU1: balance_planned | AV1: timed_passes | AW1: soak_passes | AX1: soak_s | AY1: source | AZ1: estimator
A2: 4x4 (6 ch) | B2: 15.556 | C2: 1.662 | F2: 439.27 | G2: 27.46 | J2: 11.358 | L2: 12.572 | N2: 2.3866 | P2: single engine | Q2: one 4x4 engine | R2: 4x4 | S2: 1 | T2: 6 | U2: 16 | V2: 400 | W2: 132 | X2: 195563520 | Y2: 195563520 | Z2: 0 | AA2: 7 | AB2: 98.55 | AC2: 15330.2 | AD2: 15555.8 | AE2: 15884.6 | AF2: 17218.1 | AG2: 1662.3 | AH2: 9.65 | AI2: 11.358 | AJ2: 12.572 | AK2: 27.107 | AL2: 25.512 | AM2: 1.595 | AN2: 466.73 | AO2: 439.27 | AP2: 27.46 | AQ2: 2.3866 | AR2: 27.332 | AS2: 2.1741 | AT2: 1 | AU2: 1 | AV2: 3 | AW2: 3485 | AX2: 60.01 | AY2: workload/workload_4x4_400MHz.csv | AZ2: wall time, energy: measured (60 s soak of whole passes, board power); engine time: plan cycles / clock / measured steady-state efficiency (Configurations pct_of_peak); overhead = wall - engine
A3: 8x4 (10 ch) | B3: 8.275 | C3: 2.339 | F3: 280.72 | G3: 34.24 | J3: 18.426 | L3: 23.634 | N3: 1.6106 | P3: single engine | Q3: one 8x4 engine | R3: 8x4 | S3: 1 | T3: 10 | U3: 32 | V3: 375 | W3: 132 | X3: 195563520 | Y3: 195563520 | Z3: 0 | AA3: 7 | AB3: 98.81 | AC3: 8176.1 | AD3: 8274.6 | AE3: 9062 | AF3: 10613.7 | AG3: 2339.1 | AH3: 22.04 | AI3: 18.426 | AJ3: 23.634 | AK3: 29.675 | AL3: 26.449 | AM3: 3.226 | AN3: 314.96 | AO3: 280.72 | AP3: 34.24 | AQ3: 1.6106 | AR3: 29.79 | AS3: 1.2605 | AT3: 1 | AU3: 1 | AV3: 3 | AW3: 5654 | AX3: 60.01 | AY3: workload/workload_8x4_375MHz.csv | AZ3: wall time, energy: measured (60 s soak of whole passes, board power); engine time: plan cycles / clock / measured steady-state efficiency (Configurations pct_of_peak); overhead = wall - engine
A4: 2 x 4x4 (12 ch) | D4: 7.85 | E4: 1.82 | H4: 258.91 | I4: 33 | K4: 20.222 | M4: 24.912 | O4: 1.4927 | P4: multi-tenant | Q4: 2 x 4x4 tenants | R4: 4x4 | S4: 2 | T4: 12 | U4: 32 | V4: 394 | W4: 132 | X4: 195563520 | Y4: 195563520 | Z4: 0 | AA4: 7/7 | AB4: 99.13 | AC4: 7781.9 | AD4: 7850.2 | AE4: 8589.9 | AF4: 9670.7 | AG4: 1820.5 | AH4: 18.82 | AI4: 20.222 | AJ4: 24.912 | AK4: 30.185 | AL4: 26.773 | AM4: 3.412 | AN4: 291.91 | AO4: 258.91 | AP4: 33 | AQ4: 1.4927 | AR4: 30.744 | AS4: 1.2341 | AT4: 0.9885 | AU4: 1 | AV4: 3 | AW4: 6205 | AX4: 60.01 | AY4: workload/workload_2x4x4_394MHz.csv | AZ4: wall time, energy: measured (60 s soak of whole passes, board power); engine time: plan cycles / clock / measured steady-state efficiency (Configurations pct_of_peak); overhead = wall - engine
A5: 16x3 (13 ch) | B5: 5.974 | C5: 2.693 | F5: 235.92 | G5: 24.54 | J5: 22.564 | L5: 32.737 | N5: 1.3318 | P5: single engine | Q5: one 16x3 engine | R5: 16x3 | S5: 1 | T5: 13 | U5: 48 | V5: 350 | W5: 132 | X5: 195563520 | Y5: 197061120 | Z5: 0.76 | AA5: 7 | AB5: 98.51 | AC5: 5884.8 | AD5: 5973.8 | AE5: 6951.2 | AF5: 8667.1 | AG5: 2693.3 | AH5: 31.07 | AI5: 22.564 | AJ5: 32.737 | AK5: 30.051 | AL5: 27.22 | AM5: 2.831 | AN5: 260.46 | AO5: 235.92 | AP5: 24.54 | AQ5: 1.3318 | AR5: 32.235 | AS5: 0.9847 | AT5: 1 | AU5: 1 | AV5: 3 | AW5: 6923 | AX5: 60 | AY5: workload/workload_16x3_350MHz.csv | AZ5: wall time, energy: measured (60 s soak of whole passes, board power); engine time: plan cycles / clock / measured steady-state efficiency (Configurations pct_of_peak); overhead = wall - engine
A6: 8x8 (17 ch) | B6: 4.771 | C6: 3.447 | F6: 249.96 | G6: 33.23 | J6: 23.796 | L6: 40.987 | N6: 1.4481 | P6: single engine | Q6: one 8x8 engine | R6: 8x8 | S6: 1 | T6: 17 | U6: 64 | V6: 325 | W6: 132 | X6: 195563520 | Y6: 195563520 | Z6: 0 | AA6: 7 | AB6: 98.86 | AC6: 4717 | AD6: 4771.4 | AE6: 6135.1 | AF6: 8218.2 | AG6: 3446.8 | AH6: 41.94 | AI6: 23.796 | AJ6: 40.987 | AK6: 34.46 | AL6: 30.416 | AM6: 4.044 | AN6: 283.2 | AO6: 249.96 | AP6: 33.23 | AQ6: 1.4481 | AR6: 36.286 | AS6: 0.8853 | AT6: 1 | AU6: 1 | AV6: 3 | AW6: 7301 | AX6: 60 | AY6: workload/workload_8x8_325MHz.csv | AZ6: wall time, energy: measured (60 s soak of whole passes, board power); engine time: plan cycles / clock / measured steady-state efficiency (Configurations pct_of_peak); overhead = wall - engine
A7: 3 x 4x4 (18 ch) | D7: 5.175 | E7: 2.64 | H7: 243.5 | I7: 32.34 | K7: 25.025 | M7: 37.789 | O7: 1.4105 | P7: multi-tenant | Q7: 3 x 4x4 tenants | R7: 4x4 | S7: 3 | T7: 18 | U7: 48 | V7: 399 | W7: 132 | X7: 195563520 | Y7: 195563520 | Z7: 0 | AA7: 7/7/7 | AB7: 98.99 | AC7: 5122.9 | AD7: 5175.2 | AE7: 6367 | AF7: 7814.8 | AG7: 2639.6 | AH7: 33.78 | AI7: 25.025 | AJ7: 37.789 | AK7: 35.297 | AL7: 31.159 | AM7: 4.138 | AN7: 275.84 | AO7: 243.5 | AP7: 32.34 | AQ7: 1.4105 | AR7: 37.179 | AS7: 0.9839 | AT7: 0.9921 | AU7: 1 | AV7: 3 | AW7: 7678 | AX7: 60 | AY7: workload/workload_3x4x4_399MHz.csv | AZ7: wall time, energy: measured (60 s soak of whole passes, board power); engine time: plan cycles / clock / measured steady-state efficiency (Configurations pct_of_peak); overhead = wall - engine
A8: 2 x 8x4 (20 ch) | D8: 4.304 | E8: 2.725 | H8: 224.87 | I8: 30.45 | K8: 27.819 | M8: 45.434 | O8: 1.3056 | P8: multi-tenant | Q8: 2 x 8x4 tenants | R8: 8x4 | S8: 2 | T8: 20 | U8: 64 | V8: 361 | W8: 132 | X8: 195563520 | Y8: 195563520 | Z8: 0 | AA8: 7/7 | AB8: 98.66 | AC8: 4246.6 | AD8: 4304.3 | AE8: 5487.5 | AF8: 7029.8 | AG8: 2725.5 | AH8: 38.77 | AI8: 27.819 | AJ8: 45.434 | AK8: 36.32 | AL8: 31.988 | AM8: 4.332 | AN8: 255.32 | AO8: 224.87 | AP8: 30.45 | AQ8: 1.3056 | AR8: 38.233 | AS8: 0.8415 | AT8: 0.9886 | AU8: 1 | AV8: 3 | AW8: 8536 | AX8: 60.01 | AY8: workload/workload_2x8x4_361MHz.csv | AZ8: wall time, energy: measured (60 s soak of whole passes, board power); engine time: plan cycles / clock / measured steady-state efficiency (Configurations pct_of_peak); overhead = wall - engine
A9: 4x24 (24 ch) | B9: 3.498 | C9: 4.729 | F9: 264.93 | G9: 19.69 | J9: 23.772 | L9: 55.909 | N9: 1.4553 | P9: single engine | Q9: one 4x24 engine | R9: 4x24 | S9: 1 | T9: 24 | U9: 96 | V9: 300 | W9: 132 | X9: 195563520 | Y9: 198789120 | Z9: 1.623 | AA9: 7 | AB9: 99 | AC9: 3462.9 | AD9: 3497.9 | AE9: 5395.4 | AF9: 8226.8 | AG9: 4728.9 | AH9: 57.48 | AI9: 23.772 | AJ9: 55.909 | AK9: 34.596 | AL9: 32.203 | AM9: 2.393 | AN9: 284.61 | AO9: 264.93 | AP9: 19.69 | AQ9: 1.4553 | AR9: 40.43 | AS9: 0.7231 | AT9: 1 | AU9: 1 | AV9: 3 | AW9: 7294 | AX9: 60.01 | AY9: workload/workload_4x24_300MHz.csv | AZ9: wall time, energy: measured (60 s soak of whole passes, board power); engine time: plan cycles / clock / measured steady-state efficiency (Configurations pct_of_peak); overhead = wall - engine
A10: 4 x 4x4 (24 ch) | D10: 4.143 | E10: 2.674 | H10: 222.67 | I10: 28.95 | K10: 28.689 | M10: 47.203 | O10: 1.2867 | P10: multi-tenant | Q10: 4 x 4x4 tenants | R10: 4x4 | S10: 4 | T10: 24 | U10: 64 | V10: 374 | W10: 132 | X10: 195563520 | Y10: 195563520 | Z10: 0 | AA10: 7/7/7/7 | AB10: 98.95 | AC10: 4099.6 | AD10: 4143.1 | AE10: 5623.2 | AF10: 6816.7 | AG10: 2673.6 | AH10: 39.22 | AI10: 28.689 | AJ10: 47.203 | AK10: 36.913 | AL10: 32.666 | AM10: 4.247 | AN10: 251.62 | AO10: 222.67 | AP10: 28.95 | AQ10: 1.2867 | AR10: 40.345 | AS10: 0.8547 | AT10: 0.9629 | AU10: 0.9997 | AV10: 3 | AW10: 8802 | AX10: 60 | AY10: workload/workload_4x4x4_374MHz.csv | AZ10: wall time, energy: measured (60 s soak of whole passes, board power); engine time: plan cycles / clock / measured steady-state efficiency (Configurations pct_of_peak); overhead = wall - engine
A11: 2 x 16x3 (26 ch) | D11: 3.059 | E11: 3.711 | H11: 229.4 | I11: 30.94 | K11: 28.888 | M11: 63.93 | O11: 1.3312 | P11: multi-tenant | Q11: 2 x 16x3 tenants | R11: 16x3 | S11: 2 | T11: 26 | U11: 96 | V11: 341 | W11: 132 | X11: 195563520 | Y11: 197061120 | Z11: 0.76 | AA11: 7/7 | AB11: 98.73 | AC11: 3020.2 | AD11: 3059 | AE11: 4766.7 | AF11: 6769.7 | AG11: 3710.7 | AH11: 54.81 | AI11: 28.888 | AJ11: 63.93 | AK11: 38.457 | AL11: 33.887 | AM11: 4.57 | AN11: 260.34 | AO11: 229.4 | AP11: 30.94 | AQ11: 1.3312 | AR11: 42.468 | AS11: 0.6643 | AT11: 0.9971 | AU11: 0.9999 | AV11: 3 | AW11: 8864 | AX11: 60.01 | AY11: workload/workload_2x16x3_341MHz.csv | AZ11: wall time, energy: measured (60 s soak of whole passes, board power); engine time: plan cycles / clock / measured steady-state efficiency (Configurations pct_of_peak); overhead = wall - engine
A12: 5 x 4x4 (30 ch) | D12: 3.794 | E12: 3.083 | H12: 232.29 | I12: 31.47 | K12: 28.435 | M12: 51.54 | O12: 1.3487 | P12: multi-tenant | Q12: 5 x 4x4 tenants | R12: 4x4 | S12: 5 | T12: 30 | U12: 80 | V12: 329 | W12: 132 | X12: 195563520 | Y12: 195563520 | Z12: 0 | AA12: 7/7/7/7/7 | AB12: 98.25 | AC12: 3728 | AD12: 3794.4 | AE12: 5617.3 | AF12: 6877.5 | AG12: 3083.1 | AH12: 44.83 | AI12: 28.435 | AJ12: 51.54 | AK12: 38.352 | AL12: 33.776 | AM12: 4.576 | AN12: 263.77 | AO12: 232.29 | AP12: 31.47 | AQ12: 1.3487 | AR12: 42.187 | AS12: 0.8185 | AT12: 0.9679 | AU12: 0.9997 | AV12: 3 | AW12: 8725 | AX12: 60.01 | AY12: workload/workload_5x4x4_329MHz.csv | AZ12: wall time, energy: measured (60 s soak of whole passes, board power); engine time: plan cycles / clock / measured steady-state efficiency (Configurations pct_of_peak); overhead = wall - engine
A13: 3 x 8x4 (30 ch) | D13: 2.938 | E13: 4.097 | H13: 242.75 | I13: 32.45 | K13: 27.798 | M13: 66.566 | O13: 1.4072 | P13: multi-tenant | Q13: 3 x 8x4 tenants | R13: 8x4 | S13: 3 | T13: 30 | U13: 96 | V13: 354 | W13: 132 | X13: 195563520 | Y13: 195563520 | Z13: 0 | AA13: 7/7/7 | AB13: 98.27 | AC13: 2887.1 | AD13: 2937.9 | AE13: 5134.6 | AF13: 7035.1 | AG13: 4097.2 | AH13: 58.24 | AI13: 27.798 | AJ13: 66.566 | AK13: 39.118 | AL13: 34.506 | AM13: 4.612 | AN13: 275.2 | AO13: 242.75 | AP13: 32.45 | AQ13: 1.4072 | AR13: 43.516 | AS13: 0.6537 | AT13: 0.9974 | AU13: 1 | AV13: 3 | AW13: 8529 | AX13: 60 | AY13: workload/workload_3x8x4_354MHz.csv | AZ13: wall time, energy: measured (60 s soak of whole passes, board power); engine time: plan cycles / clock / measured steady-state efficiency (Configurations pct_of_peak); overhead = wall - engine
A14: 4x32 (32 ch) | B14: 3.084 | C14: 6.565 | F14: 319.37 | G14: 22.88 | J14: 20.269 | L14: 63.42 | N14: 1.7501 | P14: single engine | Q14: one 4x32 engine | R14: 4x32 | S14: 1 | T14: 32 | U14: 128 | V14: 250 | W14: 132 | X14: 195563520 | Y14: 195563520 | Z14: 0 | AA14: 7 | AB14: 99.43 | AC14: 3066 | AD14: 3083.6 | AE14: 5612.3 | AF14: 9648.5 | AG14: 6564.9 | AH14: 68.04 | AI14: 20.269 | AJ14: 63.42 | AK14: 35.472 | AL14: 33.101 | AM14: 2.371 | AN14: 342.25 | AO14: 319.37 | AP14: 22.88 | AQ14: 1.7501 | AR14: 42.271 | AS14: 0.6665 | AT14: 1 | AU14: 1 | AV14: 3 | AW14: 6219 | AX14: 60 | AY14: workload/workload_4x32_250MHz.csv | AZ14: wall time, energy: measured (60 s soak of whole passes, board power); engine time: plan cycles / clock / measured steady-state efficiency (Configurations pct_of_peak); overhead = wall - engine

Sheet Configurations
A1: config_label | B1: gmac_s_single | C1: gmac_s_multi | D1: static_nJ_per_MAC_single | E1: dynamic_nJ_per_MAC_single | F1: static_nJ_per_MAC_multi | G1: dynamic_nJ_per_MAC_multi | H1: clock_mhz_single | I1: clock_mhz_multi | J1: gmac_s_per_channel_single | K1: gmac_s_per_channel_multi | L1: kind | M1: configuration | N1: engine_shape | O1: tenants | P1: hbm_channels | Q1: lanes_total | R1: macs_per_cycle | S1: clock_mhz | T1: gmac_s | U1: pct_of_peak | V1: gmac_s_per_channel | W1: energy_total_nJ_per_MAC | X1: board_load_W | Y1: board_idle_W | Z1: floorplan | AA1: status | AB1: source | AC1: estimator
A2: 4x4 (6 ch) | B2: 12.615 | D2: 1.9997 | E2: 0.1669 | H2: 400 | J2: 2.1025 | L2: single engine | M2: one 4x4 engine | N2: 4x4 | O2: 1 | P2: 6 | Q2: 16 | R2: 32 | S2: 400 | T2: 12.615 | U2: 98.55 | V2: 2.1025 | W2: 2.1666 | X2: 27.332 | Y2: 25.226 | Z2: SLR0 | AA2: measured | AB2: GEMV_Family_Measured.csv, family_measurements/4x4/power_4x4_400MHz.csv | AC2: steady state: ss_gflops_act_MIXED / 2; energy = MIXED soak power / that
A3: 8x4 (10 ch) | B3: 23.715 | D3: 1.1236 | E3: 0.1325 | H3: 375 | J3: 2.3715 | L3: single engine | M3: one 8x4 engine | N3: 8x4 | O3: 1 | P3: 10 | Q3: 32 | R3: 64 | S3: 375 | T3: 23.715 | U3: 98.81 | V3: 2.3715 | W3: 1.2562 | X3: 29.79 | Y3: 26.647 | Z3: SLR0 | AA3: measured | AB3: GEMV_Family_Measured.csv, family_measurements/8x4/power_8x4_375MHz.csv | AC3: steady state: ss_gflops_act_MIXED / 2; energy = MIXED soak power / that
A4: 2 x 4x4 (12 ch) | C4: 24.997 | F4: 1.0717 | G4: 0.1582 | I4: 394 | K4: 2.0831 | L4: multi-tenant | M4: 2 x 4x4 tenants | N4: 4x4 | O4: 2 | P4: 12 | Q4: 32 | R4: 64 | S4: 394 | T4: 24.997 | U4: 99.13 | V4: 2.0831 | W4: 1.2299 | X4: 30.744 | Y4: 26.789 | Z4: SLR0 | AA4: measured | AB4: multi_x2_394MHz.csv (sparse_4x4_x2_400.xclbin) | AC4: steady state: sum over tenants of MACs / (active span - a), all tenants running; energy = full-set MIXED soak power / that
A5: 16x3 (13 ch) | B5: 33.1 | D5: 0.8308 | E5: 0.143 | H5: 350 | J5: 2.5462 | L5: single engine | M5: one 16x3 engine | N5: 16x3 | O5: 1 | P5: 13 | Q5: 48 | R5: 96 | S5: 350 | T5: 33.1 | U5: 98.51 | V5: 2.5462 | W5: 0.9739 | X5: 32.235 | Y5: 27.501 | Z5: SLR0 | AA5: measured | AB5: GEMV_Family_Measured.csv, family_measurements/16x3/power_16x3_350MHz.csv | AC5: steady state: ss_gflops_act_MIXED / 2; energy = MIXED soak power / that
A6: 8x8 (17 ch) | B6: 41.125 | D6: 0.751 | E6: 0.1314 | H6: 325 | J6: 2.4191 | L6: single engine | M6: one 8x8 engine | N6: 8x8 | O6: 1 | P6: 17 | Q6: 64 | R6: 128 | S6: 325 | T6: 41.125 | U6: 98.86 | V6: 2.4191 | W6: 0.8823 | X6: 36.286 | Y6: 30.883 | Z6: split | AA6: measured | AB6: GEMV_Family_Measured.csv, family_measurements/8x8/power_8x8_325MHz.csv | AC6: steady state: ss_gflops_act_MIXED / 2; energy = MIXED soak power / that
A7: 3 x 4x4 (18 ch) | C7: 37.915 | F7: 0.8166 | G7: 0.164 | I7: 399 | K7: 2.1064 | L7: multi-tenant | M7: 3 x 4x4 tenants | N7: 4x4 | O7: 3 | P7: 18 | Q7: 48 | R7: 96 | S7: 399 | T7: 37.915 | U7: 98.99 | V7: 2.1064 | W7: 0.9806 | X7: 37.179 | Y7: 30.96 | Z7: SLR0 | AA7: measured | AB7: multi_x3_399MHz.csv (sparse_4x4_x3_400.xclbin) | AC7: steady state: sum over tenants of MACs / (active span - a), all tenants running; energy = full-set MIXED soak power / that
A8: 2 x 8x4 (20 ch) | C8: 45.591 | F8: 0.6896 | G8: 0.149 | I8: 361 | K8: 2.2795 | L8: multi-tenant | M8: 2 x 8x4 tenants | N8: 8x4 | O8: 2 | P8: 20 | Q8: 64 | R8: 128 | S8: 361 | T8: 45.591 | U8: 98.66 | V8: 2.2795 | W8: 0.8386 | X8: 38.233 | Y8: 31.438 | Z8: SLR0 | AA8: measured | AB8: multi_8x4_x2_361MHz.csv (sparse_8x4_x2_375.xclbin) | AC8: steady state: sum over tenants of MACs / (active span - a), all tenants running; energy = full-set MIXED soak power / that
A9: 4x24 (24 ch) | B9: 57.025 | D9: 0.5723 | E9: 0.1367 | H9: 300 | J9: 2.376 | L9: single engine | M9: one 4x24 engine | N9: 4x24 | O9: 1 | P9: 24 | Q9: 96 | R9: 192 | S9: 300 | T9: 57.025 | U9: 99 | V9: 2.376 | W9: 0.709 | X9: 40.43 | Y9: 32.633 | Z9: split | AA9: measured | AB9: GEMV_Family_Measured.csv, family_measurements/4x24/power_4x24_300MHz.csv | AC9: steady state: ss_gflops_act_MIXED / 2; energy = MIXED soak power / that
A10: 4 x 4x4 (24 ch) | C10: 47.37 | F10: 0.6975 | G10: 0.1542 | I10: 374 | K10: 1.9738 | L10: multi-tenant | M10: 4 x 4x4 tenants | N10: 4x4 | O10: 4 | P10: 24 | Q10: 64 | R10: 128 | S10: 374 | T10: 47.37 | U10: 98.95 | V10: 1.9738 | W10: 0.8517 | X10: 40.345 | Y10: 33.041 | Z10: SLR0 | AA10: measured | AB10: multi_x4_374MHz.csv (sparse_4x4_x4_375.xclbin) | AC10: steady state: sum over tenants of MACs / (active span - a), all tenants running; energy = full-set MIXED soak power / that
A11: 2 x 16x3 (26 ch) | C11: 64.642 | F11: 0.5318 | G11: 0.1252 | I11: 341 | K11: 2.4862 | L11: multi-tenant | M11: 2 x 16x3 tenants | N11: 16x3 | O11: 2 | P11: 26 | Q11: 96 | R11: 192 | S11: 341 | T11: 64.642 | U11: 98.73 | V11: 2.4862 | W11: 0.657 | X11: 42.468 | Y11: 34.378 | Z11: split | AA11: measured | AB11: multi_16x3_x2_341MHz.csv (sparse_16x3_x2_375.xclbin) | AC11: steady state: sum over tenants of MACs / (active span - a), all tenants running; energy = full-set MIXED soak power / that
A12: 5 x 4x4 (30 ch) | C12: 51.718 | F12: 0.6529 | G12: 0.1628 | I12: 329 | K12: 1.7239 | L12: multi-tenant | M12: 5 x 4x4 tenants | N12: 4x4 | O12: 5 | P12: 30 | Q12: 80 | R12: 160 | S12: 329 | T12: 51.718 | U12: 98.25 | V12: 1.7239 | W12: 0.8157 | X12: 42.187 | Y12: 33.768 | Z12: split | AA12: measured | AB12: multi_x5_329MHz.csv (sparse_4x4_x5_375_split.xclbin) | AC12: steady state: sum over tenants of MACs / (active span - a), all tenants running; energy = full-set MIXED soak power / that
A13: 3 x 8x4 (30 ch) | C13: 66.795 | F13: 0.5106 | G13: 0.1409 | I13: 354 | K13: 2.2265 | L13: multi-tenant | M13: 3 x 8x4 tenants | N13: 8x4 | O13: 3 | P13: 30 | Q13: 96 | R13: 192 | S13: 354 | T13: 66.795 | U13: 98.27 | V13: 2.2265 | W13: 0.6515 | X13: 43.516 | Y13: 34.106 | Z13: split | AA13: measured | AB13: multi_8x4_x3_354MHz.csv (sparse_8x4_x3_375.xclbin) | AC13: steady state: sum over tenants of MACs / (active span - a), all tenants running; energy = full-set MIXED soak power / that
A14: 4x32 (32 ch) | B14: 63.635 | D14: 0.5294 | E14: 0.1349 | H14: 250 | J14: 1.9886 | L14: single engine | M14: one 4x32 engine | N14: 4x32 | O14: 1 | P14: 32 | Q14: 128 | R14: 256 | S14: 250 | T14: 63.635 | U14: 99.43 | V14: 1.9886 | W14: 0.6643 | X14: 42.271 | Y14: 33.686 | Z14: split | AA14: measured | AB14: GEMV_Family_Measured.csv, family_measurements/4x32/power_4x32_250MHz.csv | AC14: steady state: ss_gflops_act_MIXED / 2; energy = MIXED soak power / that

Sheet MT Interference
A1: workload | B1: tenants_running | C1: slowdown_pct_t0 | D1: slowdown_pct_t1 | E1: slowdown_pct_t2 | F1: slowdown_pct_t3 | G1: slowdown_pct_t4 | H1: interference_t0 | I1: interference_t1 | J1: interference_t2 | K1: interference_t3 | L1: interference_t4 | M1: active_overlap_pct | N1: alone_spread_pct_max | O1: workload_name | P1: tenants_n | Q1: bitstream | R1: clock_mhz | S1: estimator
A2: Mixed | B2: 2 tenants | C2: 0.89 | D2: -1.07 | H2: 1.0089 | I2: 0.9893 | M2: 97.37 | N2: 0.994 | O2: Mixed | P2: 2 | Q2: sparse_4x4_x5_375_split.xclbin | R2: 329 | S2: active-span ratio vs the same tenant alone, mean of 3 reps
B3: 3 tenants | C3: 0.97 | D3: -0.66 | E3: -0.37 | H3: 1.0097 | I3: 0.9934 | J3: 0.9963 | M3: 94.27 | N3: 0.994 | O3: Mixed | P3: 3 | Q3: sparse_4x4_x5_375_split.xclbin | R3: 329 | S3: active-span ratio vs the same tenant alone, mean of 3 reps
B4: 4 tenants | C4: 1.18 | D4: -0.14 | E4: 0.05 | F4: -0.3 | H4: 1.0118 | I4: 0.9986 | J4: 1.0005 | K4: 0.997 | M4: 91.5 | N4: 0.994 | O4: Mixed | P4: 4 | Q4: sparse_4x4_x5_375_split.xclbin | R4: 329 | S4: active-span ratio vs the same tenant alone, mean of 3 reps
B5: 5 tenants | C5: 1.45 | D5: 0.04 | E5: 0.46 | F5: -0.38 | G5: -0.28 | H5: 1.0145 | I5: 1.0004 | J5: 1.0046 | K5: 0.9962 | L5: 0.9972 | M5: 88.27 | N5: 0.994 | O5: Mixed | P5: 5 | Q5: sparse_4x4_x5_375_split.xclbin | R5: 329 | S5: active-span ratio vs the same tenant alone, mean of 3 reps
A6: All 2:32 | B6: 2 tenants | C6: 0.43 | D6: -0.8 | H6: 1.0043 | I6: 0.992 | M6: 95.57 | N6: 0.441 | O6: All 2:32 | P6: 2 | Q6: sparse_4x4_x5_375_split.xclbin | R6: 329 | S6: active-span ratio vs the same tenant alone, mean of 3 reps
B7: 3 tenants | C7: 0.39 | D7: -0.8 | E7: -0.08 | H7: 1.0039 | I7: 0.992 | J7: 0.9992 | M7: 92.07 | N7: 0.441 | O7: All 2:32 | P7: 3 | Q7: sparse_4x4_x5_375_split.xclbin | R7: 329 | S7: active-span ratio vs the same tenant alone, mean of 3 reps
B8: 4 tenants | C8: 0.41 | D8: -0.64 | E8: 0.13 | F8: -0.41 | H8: 1.0041 | I8: 0.9936 | J8: 1.0013 | K8: 0.9959 | M8: 85.03 | N8: 0.441 | O8: All 2:32 | P8: 4 | Q8: sparse_4x4_x5_375_split.xclbin | R8: 329 | S8: active-span ratio vs the same tenant alone, mean of 3 reps
B9: 5 tenants | C9: 0.92 | D9: -0.06 | E9: 0.46 | F9: -0.62 | G9: -0.01 | H9: 1.0092 | I9: 0.9994 | J9: 1.0046 | K9: 0.9938 | L9: 0.9999 | M9: 83.9 | N9: 0.441 | O9: All 2:32 | P9: 5 | Q9: sparse_4x4_x5_375_split.xclbin | R9: 329 | S9: active-span ratio vs the same tenant alone, mean of 3 reps

Sheet MT Throughput
A1: tenants_running | B1: gmac_s_mixed | C1: gmac_s_all2to32 | D1: gmac_s_linear_scaling | E1: gmac_s_peak | F1: scaling_x_mixed | G1: scaling_x_all2to32 | H1: pct_of_peak_mixed | I1: pct_of_peak_all2to32 | J1: tenants_n | K1: bitstream | L1: clock_mhz | M1: estimator
A2: 1 tenant | B2: 9.881 | C2: 9.729 | D2: 9.881 | E2: 10.528 | F2: 1 | G2: 1 | H2: 93.85 | I2: 92.41 | J2: 1 | K2: sparse_4x4_x5_375_split.xclbin | L2: 329 | M2: 60 s power soak, host calculation counts x MACs per calculation
A3: 2 tenants | B3: 19.743 | C3: 19.13 | D3: 19.762 | E3: 21.056 | F3: 1.998 | G3: 1.966 | H3: 93.76 | I3: 90.85 | J3: 2 | K3: sparse_4x4_x5_375_split.xclbin | L3: 329 | M3: 60 s power soak, host calculation counts x MACs per calculation
A4: 3 tenants | B4: 29.351 | C4: 28.938 | D4: 29.643 | E4: 31.584 | F4: 2.97 | G4: 2.974 | H4: 92.93 | I4: 91.62 | J4: 3 | K4: sparse_4x4_x5_375_split.xclbin | L4: 329 | M4: 60 s power soak, host calculation counts x MACs per calculation
A5: 4 tenants | B5: 39.196 | C5: 37.706 | D5: 39.524 | E5: 42.112 | F5: 3.967 | G5: 3.876 | H5: 93.08 | I5: 89.54 | J5: 4 | K5: sparse_4x4_x5_375_split.xclbin | L5: 329 | M5: 60 s power soak, host calculation counts x MACs per calculation
A6: 5 tenants | B6: 48.543 | C6: 47.209 | D6: 49.405 | E6: 52.64 | F6: 4.913 | G6: 4.852 | H6: 92.22 | I6: 89.68 | J6: 5 | K6: sparse_4x4_x5_375_split.xclbin | L6: 329 | M6: 60 s power soak, host calculation counts x MACs per calculation

Sheet MT Energy
A1: workload | B1: tenants_running | C1: static_nJ_per_MAC | D1: dynamic_nJ_per_MAC | E1: total_nJ_per_MAC | F1: gmac_s | G1: board_load_W | H1: board_idle_W | I1: board_dynamic_W | J1: vccint_load_W | K1: vccint_idle_W | L1: static_pct | M1: workload_name | N1: tenants_n | O1: bitstream | P1: clock_mhz | Q1: estimator
A2: Mixed | B2: 1 tenant | C2: 3.4154 | D2: 0.1598 | E2: 3.5752 | F2: 9.881 | G2: 35.327 | H2: 33.748 | I2: 1.579 | J2: 9.077 | K2: 8.705 | L2: 95.53 | M2: Mixed | N2: 1 | O2: sparse_4x4_x5_375_split.xclbin | P2: 329 | Q2: 60 s power soak, host calculation counts x MACs per calculation; static = idle after the soak, dynamic = load - idle
B3: 2 tenants | C3: 1.7125 | D3: 0.1619 | E3: 1.8744 | F3: 19.743 | G3: 37.005 | H3: 33.809 | I3: 3.196 | J3: 9.342 | K3: 8.703 | L3: 91.36 | M3: Mixed | N3: 2 | O3: sparse_4x4_x5_375_split.xclbin | P3: 329 | Q3: 60 s power soak, host calculation counts x MACs per calculation; static = idle after the soak, dynamic = load - idle
B4: 3 tenants | C4: 1.1517 | D4: 0.1661 | E4: 1.3177 | F4: 29.351 | G4: 38.676 | H4: 33.802 | I4: 4.874 | J4: 9.67 | K4: 8.699 | L4: 87.4 | M4: Mixed | N4: 3 | O4: sparse_4x4_x5_375_split.xclbin | P4: 329 | Q4: 60 s power soak, host calculation counts x MACs per calculation; static = idle after the soak, dynamic = load - idle
B5: 4 tenants | C5: 0.8641 | D5: 0.1646 | E5: 1.0287 | F5: 39.196 | G5: 40.321 | H5: 33.87 | I5: 6.451 | J5: 10.018 | K5: 8.852 | L5: 84 | M5: Mixed | N5: 4 | O5: sparse_4x4_x5_375_split.xclbin | P5: 329 | Q5: 60 s power soak, host calculation counts x MACs per calculation; static = idle after the soak, dynamic = load - idle
B6: 5 tenants | C6: 0.6956 | D6: 0.1734 | E6: 0.8691 | F6: 48.543 | G6: 42.187 | H6: 33.768 | I6: 8.419 | J6: 10.465 | K6: 8.835 | L6: 80.04 | M6: Mixed | N6: 5 | O6: sparse_4x4_x5_375_split.xclbin | P6: 329 | Q6: 60 s power soak, host calculation counts x MACs per calculation; static = idle after the soak, dynamic = load - idle
A7: All 2:32 | B7: 1 tenant | C7: 3.4537 | D7: 0.1738 | E7: 3.6275 | F7: 9.729 | G7: 35.293 | H7: 33.602 | I7: 1.691 | J7: 8.97 | K7: 8.525 | L7: 95.21 | M7: All 2:32 | N7: 1 | O7: sparse_4x4_x5_375_split.xclbin | P7: 329 | Q7: 60 s power soak, host calculation counts x MACs per calculation; static = idle after the soak, dynamic = load - idle
B8: 2 tenants | C8: 1.7479 | D8: 0.1741 | E8: 1.922 | F8: 19.13 | G8: 36.767 | H8: 33.437 | I8: 3.33 | J8: 9.193 | K8: 8.522 | L8: 90.94 | M8: All 2:32 | N8: 2 | O8: sparse_4x4_x5_375_split.xclbin | P8: 329 | Q8: 60 s power soak, host calculation counts x MACs per calculation; static = idle after the soak, dynamic = load - idle
B9: 3 tenants | C9: 1.1588 | D9: 0.1713 | E9: 1.3301 | F9: 28.938 | G9: 38.49 | H9: 33.532 | I9: 4.958 | J9: 9.539 | K9: 8.516 | L9: 87.12 | M9: All 2:32 | N9: 3 | O9: sparse_4x4_x5_375_split.xclbin | P9: 329 | Q9: 60 s power soak, host calculation counts x MACs per calculation; static = idle after the soak, dynamic = load - idle
B10: 4 tenants | C10: 0.8874 | D10: 0.1756 | E10: 1.063 | F10: 37.706 | G10: 40.083 | H10: 33.461 | I10: 6.622 | J10: 9.892 | K10: 8.521 | L10: 83.48 | M10: All 2:32 | N10: 4 | O10: sparse_4x4_x5_375_split.xclbin | P10: 329 | Q10: 60 s power soak, host calculation counts x MACs per calculation; static = idle after the soak, dynamic = load - idle
B11: 5 tenants | C11: 0.7123 | D11: 0.1784 | E11: 0.8907 | F11: 47.209 | G11: 42.047 | H11: 33.626 | I11: 8.421 | J11: 10.252 | K11: 8.527 | L11: 79.97 | M11: All 2:32 | N11: 5 | O11: sparse_4x4_x5_375_split.xclbin | P11: 329 | Q11: 60 s power soak, host calculation counts x MACs per calculation; static = idle after the soak, dynamic = load - idle

Sheet Scale-out vs Scale-up
A1: metric | B1: ratio_scaleout_over_scaleup | C1: scaleout_value | D1: scaleup_value | E1: unit | F1: scaleout | G1: scaleup | H1: basis
A2: HBM channels | B2: 1 | C2: 24 | D2: 24 | E2: channels | F2: 4 x 4x4 tenants, sparse_4x4_x4_375.xclbin | G2: one 4x24 engine, family build | H2: the controlled variable: the same channel budget
A3: Kernel clock | B3: 1.2467 | C3: 374 | D3: 300 | E3: MHz | F3: 4 x 4x4 tenants, sparse_4x4_x4_375.xclbin | G3: one 4x24 engine, family build | H3: runtime clock of each bitstream
A4: MACs per cycle | B4: 0.6667 | C4: 128 | D4: 192 | E4: MACs/cycle | F4: 4 x 4x4 tenants, sparse_4x4_x4_375.xclbin | G4: one 4x24 engine, family build | H4: 4 x 32 vs 96 blocks x 2 (DSPs 512 vs 768)
A5: Throughput | B5: 0.8306 | C5: 47.365 | D5: 57.025 | E5: GMAC/s | F5: 4 x 4x4 tenants, sparse_4x4_x4_375.xclbin | G5: one 4x24 engine, family build | H5: steady state: x4 = MACs / (active span - 188 us fixed cost), all four tenants running; 4x24 = ss_gflops_act_MIXED / 2
A6: Board power | B6: 0.9979 | C6: 40.345 | D6: 40.43 | E6: W | F6: 4 x 4x4 tenants, sparse_4x4_x4_375.xclbin | G6: one 4x24 engine, family build | H6: 60 s MIXED soak, board load
A7: Energy per MAC | B7: 1.2014 | C7: 0.8518 | D7: 0.709 | E7: nJ/MAC | F7: 4 x 4x4 tenants, sparse_4x4_x4_375.xclbin | G7: one 4x24 engine, family build | H7: soak board power / steady-state GMAC/s (the family's per-W method)

Sheet Idle vs Channels
A1: build_label | B1: idle_vccint_W | C1: idle_rest_W | D1: idle_board_W | E1: hbm_channels | F1: build | G1: kind | H1: clock_mhz | I1: uses_channel_16_up | J1: n_soaks | K1: source
A2: 4x4 (6 ch) | B2: 6.048 | C2: 19.395 | D2: 25.443 | E2: 6 | F2: 4x4 | G2: single engine | H2: 400 | I2: no | J2: 5 | K2: results/family_measurements/4x4/power_4x4_400MHz.csv
A3: 8x4 (10 ch) | B3: 6.56 | C3: 20.091 | D3: 26.651 | E3: 10 | F3: 8x4 | G3: single engine | H3: 375 | I3: no | J3: 5 | K3: results/family_measurements/8x4/power_8x4_375MHz.csv
A4: 2 x 4x4 (12 ch) | B4: 6.655 | C4: 20.108 | D4: 26.764 | E4: 12 | F4: 4x4_x2 | G4: multi-tenant | H4: 394 | I4: no | J4: 2 | K4: multi_x2_394MHz.csv, multi_x2_394MHz_all2to32.csv
A5: 16x3 (13 ch) | B5: 7.139 | C5: 20.448 | D5: 27.587 | E5: 13 | F5: 16x3 | G5: single engine | H5: 350 | I5: no | J5: 5 | K5: results/family_measurements/16x3/power_16x3_350MHz.csv
A6: 8x8 (17 ch) | B6: 7.528 | C6: 23.309 | D6: 30.837 | E6: 17 | F6: 8x8 | G6: single engine | H6: 325 | I6: yes | J6: 5 | K6: results/family_measurements/8x8/power_8x8_325MHz.csv
A7: 3 x 4x4 (18 ch) | B7: 7.514 | C7: 23.353 | D7: 30.867 | E7: 18 | F7: 4x4_x3 | G7: multi-tenant | H7: 399 | I7: yes | J7: 3 | K7: multi_x3_399MHz.csv, multi_x3_399MHz_all2to32.csv
A8: 2 x 8x4 (20 ch) | B8: 7.716 | C8: 23.669 | D8: 31.386 | E8: 20 | F8: 8x4_x2 | G8: multi-tenant | H8: 361 | I8: yes | J8: 2 | K8: multi_8x4_x2_361MHz.csv, multi_8x4_x2_361MHz_all2to32.csv
A9: 4x24 (24 ch) | B9: 8.287 | C9: 24.259 | D9: 32.546 | E9: 24 | F9: 4x24 | G9: single engine | H9: 300 | I9: yes | J9: 5 | K9: results/family_measurements/4x24/power_4x24_300MHz.csv
A10: 4 x 4x4 (24 ch) | B10: 8.365 | C10: 24.416 | D10: 32.782 | E10: 24 | F10: 4x4_x4 | G10: multi-tenant | H10: 374 | I10: yes | J10: 8 | K10: multi_x4_374MHz.csv, multi_x4_374MHz_all2to32.csv
A11: 2 x 16x3 (26 ch) | B11: 9.048 | C11: 25.084 | D11: 34.132 | E11: 26 | F11: 16x3_x2 | G11: multi-tenant | H11: 341 | I11: yes | J11: 4 | K11: multi_16x3_x2_341MHz.csv, multi_16x3_x2_341MHz_all2to32.csv
A12: 5 x 4x4 (30 ch) | B12: 8.64 | C12: 25.025 | D12: 33.665 | E12: 30 | F12: 4x4_x5 | G12: multi-tenant | H12: 329 | I12: yes | J12: 10 | K12: multi_x5_329MHz.csv, multi_x5_329MHz_all2to32.csv
A13: 3 x 8x4 (30 ch) | B13: 8.877 | C13: 25.183 | D13: 34.061 | E13: 30 | F13: 8x4_x3 | G13: multi-tenant | H13: 354 | I13: yes | J13: 6 | K13: multi_8x4_x3_354MHz.csv, multi_8x4_x3_354MHz_all2to32.csv
A14: 4x32 (32 ch) | B14: 8.612 | C14: 25.039 | D14: 33.651 | E14: 32 | F14: 4x32 | G14: single engine | H14: 250 | I14: yes | J14: 5 | K14: results/family_measurements/4x32/power_4x32_250MHz.csv

Sheet Family Mixed Latency
A1: dimensions | B1: latency_us_4x4 | C1: latency_us_8x4 | D1: latency_us_16x3 | E1: latency_us_8x8 | F1: latency_us_4x24 | G1: latency_us_4x32 | H1: padding_rows_4x4 | I1: padding_rows_8x4 | J1: padding_rows_16x3 | K1: padding_rows_8x8 | L1: padding_rows_4x24 | M1: padding_rows_4x32 | N1: shape | O1: shape_order | P1: M_rows | Q1: N_cols | R1: matrix_elements | S1: data_source
A2: 512x512 | B2: 4.9106 | C2: 2.6391 | D2: 2.105 | E2: 1.5054 | F2: 1.6302 | G2: 0.9699 | H2: 0 | I2: 0 | J2: 64 | K2: 0 | L2: 256 | M2: 0 | N2: G1 | O2: 1 | P2: 512 | Q2: 512 | R2: 262144 | S2: shapes_<tag>_<MHz>_MIXED.csv latency_per_matrix_us, per-sweep overhead fit, each family at its own clock
A3: 768x768 | B3: 11.0585 | C3: 5.8828 | D3: 4.1964 | E3: 3.3788 | F3: 2.4612 | G3: 2.8801 | H3: 0 | I3: 0 | J3: 0 | K3: 0 | L3: 0 | M3: 256 | N3: G2 | O3: 2 | P3: 768 | Q3: 768 | R3: 589824 | S3: shapes_<tag>_<MHz>_MIXED.csv latency_per_matrix_us, per-sweep overhead fit, each family at its own clock
A4: 1024x1024 | B4: 19.4883 | C4: 10.4333 | D4: 8.3294 | E4: 5.972 | F4: 4.8741 | G4: 3.8021 | H4: 0 | I4: 0 | J4: 128 | K4: 0 | L4: 128 | M4: 0 | N4: G3 | O4: 3 | P4: 1024 | Q4: 1024 | R4: 1048576 | S4: shapes_<tag>_<MHz>_MIXED.csv latency_per_matrix_us, per-sweep overhead fit, each family at its own clock
A5: 3072x768 | B5: 44.1648 | C5: 23.4419 | D5: 16.5832 | E5: 13.5523 | F5: 9.8202 | G5: 8.8222 | H5: 0 | I5: 0 | J5: 0 | K5: 0 | L5: 0 | M5: 0 | N5: G4 | O5: 4 | P5: 3072 | Q5: 768 | R5: 2359296 | S5: shapes_<tag>_<MHz>_MIXED.csv latency_per_matrix_us, per-sweep overhead fit, each family at its own clock
A6: 768x3072 | B6: 43.5779 | C6: 23.3579 | D6: 16.564 | E6: 13.3446 | F6: 9.7149 | G6: 11.4574 | H6: 0 | I6: 0 | J6: 0 | K6: 0 | L6: 0 | M6: 256 | N6: G5 | O6: 5 | P6: 768 | Q6: 3072 | R6: 2359296 | S6: shapes_<tag>_<MHz>_MIXED.csv latency_per_matrix_us, per-sweep overhead fit, each family at its own clock
A7: 4096x1024 | B7: 78.1175 | C7: 42.0355 | D7: 30.3086 | E7: 24.0229 | F7: 17.8304 | G7: 15.4469 | H7: 0 | I7: 0 | J7: 128 | K7: 0 | L7: 128 | M7: 0 | N7: G6 | O7: 6 | P7: 4096 | Q7: 1024 | R7: 4194304 | S7: shapes_<tag>_<MHz>_MIXED.csv latency_per_matrix_us, per-sweep overhead fit, each family at its own clock
A8: 1024x4096 | B8: 77.3105 | C8: 41.3539 | D8: 33.2667 | E8: 23.8428 | F8: 19.1567 | G8: 15.3556 | H8: 0 | I8: 0 | J8: 128 | K8: 0 | L8: 128 | M8: 0 | N8: G7 | O8: 7 | P8: 1024 | Q8: 4096 | R8: 4194304 | S8: shapes_<tag>_<MHz>_MIXED.csv latency_per_matrix_us, per-sweep overhead fit, each family at its own clock
A9: 2048x2048 | B9: 77.7627 | C9: 41.6508 | D9: 30.5019 | E9: 23.694 | F9: 19.4485 | G9: 15.3422 | H9: 0 | I9: 0 | J9: 64 | K9: 0 | L9: 256 | M9: 0 | N9: G8 | O9: 8 | P9: 2048 | Q9: 2048 | R9: 4194304 | S9: shapes_<tag>_<MHz>_MIXED.csv latency_per_matrix_us, per-sweep overhead fit, each family at its own clock
A10: 4096x4096 | B10: 310.609 | C10: 167.6192 | D10: 120.8005 | E10: 94.8771 | F10: 71.2833 | G10: 61.6223 | H10: 0 | I10: 0 | J10: 128 | K10: 0 | L10: 128 | M10: 0 | N10: G9 | O10: 9 | P10: 4096 | Q10: 4096 | R10: 16777216 | S10: shapes_<tag>_<MHz>_MIXED.csv latency_per_matrix_us, per-sweep overhead fit, each family at its own clock
A11: 8192x2048 | B11: 309.0082 | C11: 166.7927 | D11: 117.0011 | E11: 94.5814 | F11: 71.7843 | G11: 61.404 | H11: 0 | I11: 0 | J11: 64 | K11: 0 | L11: 256 | M11: 0 | N11: G10 | O11: 10 | P11: 8192 | Q11: 2048 | R11: 16777216 | S11: shapes_<tag>_<MHz>_MIXED.csv latency_per_matrix_us, per-sweep overhead fit, each family at its own clock
A12: 2048x8192 | B12: 309.4496 | C12: 165.6937 | D12: 121.2366 | E12: 95.1581 | F12: 76.4822 | G12: 61.6403 | H12: 0 | I12: 0 | J12: 64 | K12: 0 | L12: 256 | M12: 0 | N12: G11 | O12: 11 | P12: 2048 | Q12: 8192 | R12: 16777216 | S12: shapes_<tag>_<MHz>_MIXED.csv latency_per_matrix_us, per-sweep overhead fit, each family at its own clock

Sheet Family Mixed Energy
A1: shape_group | B1: family | C1: energy_static_uJ | D1: energy_dynamic_uJ | E1: energy_static_pJ_per_element | F1: energy_dynamic_pJ_per_element | G1: energy_total_uJ | H1: energy_total_pJ_per_element | I1: dimensions | J1: shape | K1: shape_order | L1: family_order | M1: clock_mhz | N1: M_rows | O1: N_cols | P1: matrix_elements | Q1: padding_rows | R1: latency_per_matrix_us | S1: board_load_W | T1: board_idle_W | U1: board_dynamic_W | V1: static_pct | W1: data_source
A2: 512x512 | B2: 4x4 | C2: 123.875 | D2: 10.342 | E2: 472.545 | F2: 39.451 | G2: 134.217 | H2: 511.995 | I2: 512x512 | J2: G1 | K2: 1 | L2: 1 | M2: 400 | N2: 512 | O2: 512 | P2: 262144 | Q2: 0 | R2: 4.9106 | S2: 27.332 | T2: 25.226 | U2: 2.106 | V2: 92.29 | W2: latency x the family's own MIXED 60 s soak (board load / idle)
B3: 8x4 | C3: 70.324 | D3: 8.295 | E3: 268.265 | F3: 31.642 | G3: 78.619 | H3: 299.907 | I3: 512x512 | J3: G1 | K3: 1 | L3: 2 | M3: 375 | N3: 512 | O3: 512 | P3: 262144 | Q3: 0 | R3: 2.6391 | S3: 29.79 | T3: 26.647 | U3: 3.143 | V3: 89.45 | W3: latency x the family's own MIXED 60 s soak (board load / idle)
B4: 16x3 | C4: 57.89 | D4: 9.965 | E4: 220.831 | F4: 38.014 | G4: 67.855 | H4: 258.845 | I4: 512x512 | J4: G1 | K4: 1 | L4: 3 | M4: 350 | N4: 512 | O4: 512 | P4: 262144 | Q4: 64 | R4: 2.105 | S4: 32.235 | T4: 27.501 | U4: 4.734 | V4: 85.31 | W4: latency x the family's own MIXED 60 s soak (board load / idle)
B5: 8x8 | C5: 46.491 | D5: 8.134 | E5: 177.35 | F5: 31.028 | G5: 54.625 | H5: 208.378 | I5: 512x512 | J5: G1 | K5: 1 | L5: 4 | M5: 325 | N5: 512 | O5: 512 | P5: 262144 | Q5: 0 | R5: 1.5054 | S5: 36.286 | T5: 30.883 | U5: 5.403 | V5: 85.11 | W5: latency x the family's own MIXED 60 s soak (board load / idle)
B6: 4x24 | C6: 53.198 | D6: 12.711 | E6: 202.935 | F6: 48.487 | G6: 65.909 | H6: 251.423 | I6: 512x512 | J6: G1 | K6: 1 | L6: 5 | M6: 300 | N6: 512 | O6: 512 | P6: 262144 | Q6: 256 | R6: 1.6302 | S6: 40.43 | T6: 32.633 | U6: 7.797 | V6: 80.71 | W6: latency x the family's own MIXED 60 s soak (board load / idle)
B7: 4x32 | C7: 32.672 | D7: 8.327 | E7: 124.634 | F7: 31.763 | G7: 40.999 | H7: 156.397 | I7: 512x512 | J7: G1 | K7: 1 | L7: 6 | M7: 250 | N7: 512 | O7: 512 | P7: 262144 | Q7: 0 | R7: 0.9699 | S7: 42.271 | T7: 33.686 | U7: 8.585 | V7: 79.69 | W7: latency x the family's own MIXED 60 s soak (board load / idle)
A8: 768x768 | B8: 4x4 | C8: 278.962 | D8: 23.289 | E8: 472.958 | F8: 39.485 | G8: 302.251 | H8: 512.443 | I8: 768x768 | J8: G2 | K8: 2 | L8: 1 | M8: 400 | N8: 768 | O8: 768 | P8: 589824 | Q8: 0 | R8: 11.0585 | S8: 27.332 | T8: 25.226 | U8: 2.106 | V8: 92.29 | W8: latency x the family's own MIXED 60 s soak (board load / idle)
B9: 8x4 | C9: 156.759 | D9: 18.49 | E9: 265.772 | F9: 31.348 | G9: 175.249 | H9: 297.12 | I9: 768x768 | J9: G2 | K9: 2 | L9: 2 | M9: 375 | N9: 768 | O9: 768 | P9: 589824 | Q9: 0 | R9: 5.8828 | S9: 29.79 | T9: 26.647 | U9: 3.143 | V9: 89.45 | W9: latency x the family's own MIXED 60 s soak (board load / idle)
B10: 16x3 | C10: 115.405 | D10: 19.866 | E10: 195.66 | F10: 33.681 | G10: 135.271 | H10: 229.341 | I10: 768x768 | J10: G2 | K10: 2 | L10: 3 | M10: 350 | N10: 768 | O10: 768 | P10: 589824 | Q10: 0 | R10: 4.1964 | S10: 32.235 | T10: 27.501 | U10: 4.734 | V10: 85.31 | W10: latency x the family's own MIXED 60 s soak (board load / idle)
B11: 8x8 | C11: 104.347 | D11: 18.256 | E11: 176.913 | F11: 30.951 | G11: 122.603 | H11: 207.864 | I11: 768x768 | J11: G2 | K11: 2 | L11: 4 | M11: 325 | N11: 768 | O11: 768 | P11: 589824 | Q11: 0 | R11: 3.3788 | S11: 36.286 | T11: 30.883 | U11: 5.403 | V11: 85.11 | W11: latency x the family's own MIXED 60 s soak (board load / idle)
B12: 4x24 | C12: 80.316 | D12: 19.19 | E12: 136.17 | F12: 32.535 | G12: 99.506 | H12: 168.705 | I12: 768x768 | J12: G2 | K12: 2 | L12: 5 | M12: 300 | N12: 768 | O12: 768 | P12: 589824 | Q12: 0 | R12: 2.4612 | S12: 40.43 | T12: 32.633 | U12: 7.797 | V12: 80.71 | W12: latency x the family's own MIXED 60 s soak (board load / idle)
B13: 4x32 | C13: 97.019 | D13: 24.726 | E13: 164.488 | F13: 41.92 | G13: 121.745 | H13: 206.409 | I13: 768x768 | J13: G2 | K13: 2 | L13: 6 | M13: 250 | N13: 768 | O13: 768 | P13: 589824 | Q13: 256 | R13: 2.8801 | S13: 42.271 | T13: 33.686 | U13: 8.585 | V13: 79.69 | W13: latency x the family's own MIXED 60 s soak (board load / idle)
A14: 1024x1024 | B14: 4x4 | C14: 491.612 | D14: 41.042 | E14: 468.838 | F14: 39.141 | G14: 532.654 | H14: 507.979 | I14: 1024x1024 | J14: G3 | K14: 3 | L14: 1 | M14: 400 | N14: 1024 | O14: 1024 | P14: 1048576 | Q14: 0 | R14: 19.4883 | S14: 27.332 | T14: 25.226 | U14: 2.106 | V14: 92.29 | W14: latency x the family's own MIXED 60 s soak (board load / idle)
B15: 8x4 | C15: 278.016 | D15: 32.792 | E15: 265.137 | F15: 31.273 | G15: 310.808 | H15: 296.41 | I15: 1024x1024 | J15: G3 | K15: 3 | L15: 2 | M15: 375 | N15: 1024 | O15: 1024 | P15: 1048576 | Q15: 0 | R15: 10.4333 | S15: 29.79 | T15: 26.647 | U15: 3.143 | V15: 89.45 | W15: latency x the family's own MIXED 60 s soak (board load / idle)
B16: 16x3 | C16: 229.067 | D16: 39.431 | E16: 218.455 | F16: 37.605 | G16: 268.498 | H16: 256.06 | I16: 1024x1024 | J16: G3 | K16: 3 | L16: 3 | M16: 350 | N16: 1024 | O16: 1024 | P16: 1048576 | Q16: 128 | R16: 8.3294 | S16: 32.235 | T16: 27.501 | U16: 4.734 | V16: 85.31 | W16: latency x the family's own MIXED 60 s soak (board load / idle)
B17: 8x8 | C17: 184.433 | D17: 32.267 | E17: 175.889 | F17: 30.772 | G17: 216.7 | H17: 206.661 | I17: 1024x1024 | J17: G3 | K17: 3 | L17: 4 | M17: 325 | N17: 1024 | O17: 1024 | P17: 1048576 | Q17: 0 | R17: 5.972 | S17: 36.286 | T17: 30.883 | U17: 5.403 | V17: 85.11 | W17: latency x the family's own MIXED 60 s soak (board load / idle)
B18: 4x24 | C18: 159.057 | D18: 38.003 | E18: 151.688 | F18: 36.243 | G18: 197.06 | H18: 187.931 | I18: 1024x1024 | J18: G3 | K18: 3 | L18: 5 | M18: 300 | N18: 1024 | O18: 1024 | P18: 1048576 | Q18: 128 | R18: 4.8741 | S18: 40.43 | T18: 32.633 | U18: 7.797 | V18: 80.71 | W18: latency x the family's own MIXED 60 s soak (board load / idle)
B19: 4x32 | C19: 128.078 | D19: 32.641 | E19: 122.144 | F19: 31.129 | G19: 160.719 | H19: 153.273 | I19: 1024x1024 | J19: G3 | K19: 3 | L19: 6 | M19: 250 | N19: 1024 | O19: 1024 | P19: 1048576 | Q19: 0 | R19: 3.8021 | S19: 42.271 | T19: 33.686 | U19: 8.585 | V19: 79.69 | W19: latency x the family's own MIXED 60 s soak (board load / idle)
A20: 3072x768 | B20: 4x4 | C20: 1114.101 | D20: 93.011 | E20: 472.218 | F20: 39.423 | G20: 1207.112 | H20: 511.641 | I20: 3072x768 | J20: G4 | K20: 4 | L20: 1 | M20: 400 | N20: 3072 | O20: 768 | P20: 2359296 | Q20: 0 | R20: 44.1648 | S20: 27.332 | T20: 25.226 | U20: 2.106 | V20: 92.29 | W20: latency x the family's own MIXED 60 s soak (board load / idle)
B21: 8x4 | C21: 624.656 | D21: 73.678 | E21: 264.764 | F21: 31.229 | G21: 698.334 | H21: 295.993 | I21: 3072x768 | J21: G4 | K21: 4 | L21: 2 | M21: 375 | N21: 3072 | O21: 768 | P21: 2359296 | Q21: 0 | R21: 23.4419 | S21: 29.79 | T21: 26.647 | U21: 3.143 | V21: 89.45 | W21: latency x the family's own MIXED 60 s soak (board load / idle)
B22: 16x3 | C22: 456.055 | D22: 78.505 | E22: 193.301 | F22: 33.275 | G22: 534.559 | H22: 226.576 | I22: 3072x768 | J22: G4 | K22: 4 | L22: 3 | M22: 350 | N22: 3072 | O22: 768 | P22: 2359296 | Q22: 0 | R22: 16.5832 | S22: 32.235 | T22: 27.501 | U22: 4.734 | V22: 85.31 | W22: latency x the family's own MIXED 60 s soak (board load / idle)
B23: 8x8 | C23: 418.536 | D23: 73.223 | E23: 177.399 | F23: 31.036 | G23: 491.759 | H23: 208.435 | I23: 3072x768 | J23: G4 | K23: 4 | L23: 4 | M23: 325 | N23: 3072 | O23: 768 | P23: 2359296 | Q23: 0 | R23: 13.5523 | S23: 36.286 | T23: 30.883 | U23: 5.403 | V23: 85.11 | W23: latency x the family's own MIXED 60 s soak (board load / idle)
B24: 4x24 | C24: 320.463 | D24: 76.568 | E24: 135.83 | F24: 32.454 | G24: 397.031 | H24: 168.284 | I24: 3072x768 | J24: G4 | K24: 4 | L24: 5 | M24: 300 | N24: 3072 | O24: 768 | P24: 2359296 | Q24: 0 | R24: 9.8202 | S24: 40.43 | T24: 32.633 | U24: 7.797 | V24: 80.71 | W24: latency x the family's own MIXED 60 s soak (board load / idle)
B25: 4x32 | C25: 297.185 | D25: 75.739 | E25: 125.963 | F25: 32.102 | G25: 372.923 | H25: 158.065 | I25: 3072x768 | J25: G4 | K25: 4 | L25: 6 | M25: 250 | N25: 3072 | O25: 768 | P25: 2359296 | Q25: 0 | R25: 8.8222 | S25: 42.271 | T25: 33.686 | U25: 8.585 | V25: 79.69 | W25: latency x the family's own MIXED 60 s soak (board load / idle)
A26: 768x3072 | B26: 4x4 | C26: 1099.296 | D26: 91.775 | E26: 465.942 | F26: 38.899 | G26: 1191.071 | H26: 504.842 | I26: 768x3072 | J26: G5 | K26: 5 | L26: 1 | M26: 400 | N26: 768 | O26: 3072 | P26: 2359296 | Q26: 0 | R26: 43.5779 | S26: 27.332 | T26: 25.226 | U26: 2.106 | V26: 92.29 | W26: latency x the family's own MIXED 60 s soak (board load / idle)
B27: 8x4 | C27: 622.418 | D27: 73.414 | E27: 263.815 | F27: 31.117 | G27: 695.832 | H27: 294.932 | I27: 768x3072 | J27: G5 | K27: 5 | L27: 2 | M27: 375 | N27: 768 | O27: 3072 | P27: 2359296 | Q27: 0 | R27: 23.3579 | S27: 29.79 | T27: 26.647 | U27: 3.143 | V27: 89.45 | W27: latency x the family's own MIXED 60 s soak (board load / idle)
B28: 16x3 | C28: 455.527 | D28: 78.414 | E28: 193.077 | F28: 33.236 | G28: 533.941 | H28: 226.314 | I28: 768x3072 | J28: G5 | K28: 5 | L28: 3 | M28: 350 | N28: 768 | O28: 3072 | P28: 2359296 | Q28: 0 | R28: 16.564 | S28: 32.235 | T28: 27.501 | U28: 4.734 | V28: 85.31 | W28: latency x the family's own MIXED 60 s soak (board load / idle)
B29: 8x8 | C29: 412.121 | D29: 72.101 | E29: 174.68 | F29: 30.56 | G29: 484.222 | H29: 205.24 | I29: 768x3072 | J29: G5 | K29: 5 | L29: 4 | M29: 325 | N29: 768 | O29: 3072 | P29: 2359296 | Q29: 0 | R29: 13.3446 | S29: 36.286 | T29: 30.883 | U29: 5.403 | V29: 85.11 | W29: latency x the family's own MIXED 60 s soak (board load / idle)
B30: 4x24 | C30: 317.026 | D30: 75.747 | E30: 134.373 | F30: 32.106 | G30: 392.773 | H30: 166.479 | I30: 768x3072 | J30: G5 | K30: 5 | L30: 5 | M30: 300 | N30: 768 | O30: 3072 | P30: 2359296 | Q30: 0 | R30: 9.7149 | S30: 40.43 | T30: 32.633 | U30: 7.797 | V30: 80.71 | W30: latency x the family's own MIXED 60 s soak (board load / idle)
B31: 4x32 | C31: 385.954 | D31: 98.362 | E31: 163.589 | F31: 41.691 | G31: 484.316 | H31: 205.28 | I31: 768x3072 | J31: G5 | K31: 5 | L31: 6 | M31: 250 | N31: 768 | O31: 3072 | P31: 2359296 | Q31: 256 | R31: 11.4574 | S31: 42.271 | T31: 33.686 | U31: 8.585 | V31: 79.69 | W31: latency x the family's own MIXED 60 s soak (board load / idle)
A32: 4096x1024 | B32: 4x4 | C32: 1970.592 | D32: 164.515 | E32: 469.826 | F32: 39.224 | G32: 2135.108 | H32: 509.049 | I32: 4096x1024 | J32: G6 | K32: 6 | L32: 1 | M32: 400 | N32: 4096 | O32: 1024 | P32: 4194304 | Q32: 0 | R32: 78.1175 | S32: 27.332 | T32: 25.226 | U32: 2.106 | V32: 92.29 | W32: latency x the family's own MIXED 60 s soak (board load / idle)
B33: 8x4 | C33: 1120.12 | D33: 132.118 | E33: 267.057 | F33: 31.499 | G33: 1252.238 | H33: 298.557 | I33: 4096x1024 | J33: G6 | K33: 6 | L33: 2 | M33: 375 | N33: 4096 | O33: 1024 | P33: 4194304 | Q33: 0 | R33: 42.0355 | S33: 29.79 | T33: 26.647 | U33: 3.143 | V33: 89.45 | W33: latency x the family's own MIXED 60 s soak (board load / idle)
B34: 16x3 | C34: 833.517 | D34: 143.481 | E34: 198.726 | F34: 34.209 | G34: 976.998 | H34: 232.934 | I34: 4096x1024 | J34: G6 | K34: 6 | L34: 3 | M34: 350 | N34: 4096 | O34: 1024 | P34: 4194304 | Q34: 128 | R34: 30.3086 | S34: 32.235 | T34: 27.501 | U34: 4.734 | V34: 85.31 | W34: latency x the family's own MIXED 60 s soak (board load / idle)
B35: 8x8 | C35: 741.899 | D35: 129.796 | E35: 176.883 | F35: 30.946 | G35: 871.695 | H35: 207.828 | I35: 4096x1024 | J35: G6 | K35: 6 | L35: 4 | M35: 325 | N35: 4096 | O35: 1024 | P35: 4194304 | Q35: 0 | R35: 24.0229 | S35: 36.286 | T35: 30.883 | U35: 5.403 | V35: 85.11 | W35: latency x the family's own MIXED 60 s soak (board load / idle)
B36: 4x24 | C36: 581.859 | D36: 139.024 | E36: 138.726 | F36: 33.146 | G36: 720.883 | H36: 171.872 | I36: 4096x1024 | J36: G6 | K36: 6 | L36: 5 | M36: 300 | N36: 4096 | O36: 1024 | P36: 4194304 | Q36: 128 | R36: 17.8304 | S36: 40.43 | T36: 32.633 | U36: 7.797 | V36: 80.71 | W36: latency x the family's own MIXED 60 s soak (board load / idle)
B37: 4x32 | C37: 520.344 | D37: 132.612 | E37: 124.06 | F37: 31.617 | G37: 652.956 | H37: 155.677 | I37: 4096x1024 | J37: G6 | K37: 6 | L37: 6 | M37: 250 | N37: 4096 | O37: 1024 | P37: 4194304 | Q37: 0 | R37: 15.4469 | S37: 42.271 | T37: 33.686 | U37: 8.585 | V37: 79.69 | W37: latency x the family's own MIXED 60 s soak (board load / idle)
A38: 1024x4096 | B38: 4x4 | C38: 1950.235 | D38: 162.816 | E38: 464.972 | F38: 38.818 | G38: 2113.051 | H38: 503.791 | I38: 1024x4096 | J38: G7 | K38: 7 | L38: 1 | M38: 400 | N38: 1024 | O38: 4096 | P38: 4194304 | Q38: 0 | R38: 77.3105 | S38: 27.332 | T38: 25.226 | U38: 2.106 | V38: 92.29 | W38: latency x the family's own MIXED 60 s soak (board load / idle)
B39: 8x4 | C39: 1101.957 | D39: 129.975 | E39: 262.727 | F39: 30.989 | G39: 1231.933 | H39: 293.716 | I39: 1024x4096 | J39: G7 | K39: 7 | L39: 2 | M39: 375 | N39: 1024 | O39: 4096 | P39: 4194304 | Q39: 0 | R39: 41.3539 | S39: 29.79 | T39: 26.647 | U39: 3.143 | V39: 89.45 | W39: latency x the family's own MIXED 60 s soak (board load / idle)
B40: 16x3 | C40: 914.868 | D40: 157.485 | E40: 218.121 | F40: 37.547 | G40: 1072.352 | H40: 255.669 | I40: 1024x4096 | J40: G7 | K40: 7 | L40: 3 | M40: 350 | N40: 1024 | O40: 4096 | P40: 4194304 | Q40: 128 | R40: 33.2667 | S40: 32.235 | T40: 27.501 | U40: 4.734 | V40: 85.31 | W40: latency x the family's own MIXED 60 s soak (board load / idle)
...

Sheet Family Utilization
A1: family | B1: config | C1: blocks_total | D1: lut_util_pct | E1: ff_util_pct | F1: bram_util_pct | G1: dsp_util_pct | H1: hbm_channel_util_pct | I1: lut_used | J1: ff_used | K1: bram_used | L1: dsp_used | M1: hbm_channels_used | N1: lut_available | O1: ff_available | P1: bram_available | Q1: dsp_available | R1: hbm_channels_available | S1: platform_lut | T1: kernels_lut | U1: engine_dsp | V1: report_dir
A2: 4x4 (T=16) | B2: 4x4 | C2: 16 | D2: 10.44 | E2: 7.73 | F2: 15.85 | G2: 1.46 | H2: 18.75 | I2: 136008 | J2: 201446 | K2: 319.5 | L2: 132 | M2: 6 | N2: 1302720 | O2: 2607360 | P2: 2016 | Q2: 9024 | R2: 32 | S2: 108367 | T2: 27663 | U2: 128 | V2: reports_4x4_400_slr0
A3: 8x4 (T=32) | B3: 8x4 | C3: 32 | D3: 12.66 | E3: 9.37 | F3: 19.1 | G3: 2.88 | H3: 31.25 | I3: 164951 | J3: 244328 | K3: 385 | L3: 260 | M3: 10 | N3: 1302720 | O3: 2607360 | P3: 2016 | Q3: 9024 | R3: 32 | S3: 113619 | T3: 51369 | U3: 256 | V3: reports_8x4_375
A4: 16x3 (T=48) | B4: 16x3 | C4: 48 | D4: 14.9 | E4: 11 | F4: 22.57 | G4: 4.3 | H4: 40.625 | I4: 194167 | J4: 286698 | K4: 455 | L4: 388 | M4: 13 | N4: 1302720 | O4: 2607360 | P4: 2016 | Q4: 9024 | R4: 32 | S4: 117826 | T4: 76397 | U4: 384 | V4: reports_16x3_350_missed
A5: 8x8 (T=64) | B5: 8x8 | C5: 64 | D5: 16.83 | E5: 12.61 | F5: 26.02 | G5: 5.72 | H5: 53.125 | I5: 219205 | J5: 328755 | K5: 524.5 | L5: 516 | M5: 17 | N5: 1302720 | O5: 2607360 | P5: 2016 | Q5: 9024 | R5: 32 | S5: 123857 | T5: 95408 | U5: 512 | V5: reports_325
A6: 4x24 (T=96) | B6: 4x24 | C6: 96 | D6: 20.62 | E6: 15.65 | F6: 32.84 | G6: 8.55 | H6: 75 | I6: 268592 | J6: 408136 | K6: 662 | L6: 772 | M6: 24 | N6: 1302720 | O6: 2607360 | P6: 2016 | Q6: 9024 | R6: 32 | S6: 133427 | T6: 135243 | U6: 768 | V6: reports_4x24_300
A7: 4x32 (T=128) | B7: 4x32 | C7: 128 | D7: 25.08 | E7: 19.56 | F7: 39.83 | G7: 11.39 | H7: 100 | I7: 326752 | J7: 509949 | K7: 803 | L7: 1028 | M7: 32 | N7: 1302720 | O7: 2607360 | P7: 2016 | Q7: 9024 | R7: 32 | S7: 149164 | T7: 177696 | U7: 1024 | V7: reports_4x32_250

Sheet Family Measured
A1: family | B1: config | C1: cores | D1: blocks | E1: blocks_total | F1: dsps | G1: hbm_pcs | H1: host_cus | I1: macs_per_beat | J1: freq_ooc_fmax_mhz | K1: freq_closed_mhz | L1: freq_achieved_mhz | M1: freq_closed_over_ooc | N1: ss_overhead_us | O1: ss_overhead_se_us | P1: ss_gflops_act_ceiling | Q1: soak_board_W_2to4 | R1: soak_board_W_2to8 | S1: soak_board_W_2to16 | T1: soak_board_W_2to32 | U1: soak_board_W_MIXED | V1: ss_gflops_eff_2to4 | W1: ss_gflops_eff_2to8 | X1: ss_gflops_eff_2to16 | Y1: ss_gflops_eff_2to32 | Z1: ss_gflops_eff_MIXED | AA1: ss_gflops_act_2to4 | AB1: ss_gflops_act_2to8 | AC1: ss_gflops_act_2to16 | AD1: ss_gflops_act_2to32 | AE1: ss_gflops_act_MIXED | AF1: ss_efficiency_pct_2to4 | AG1: ss_efficiency_pct_2to8 | AH1: ss_efficiency_pct_2to16 | AI1: ss_efficiency_pct_2to32 | AJ1: ss_efficiency_pct_MIXED | AK1: ss_effective_mhz_2to4 | AL1: ss_effective_mhz_2to8 | AM1: ss_effective_mhz_2to16 | AN1: ss_effective_mhz_2to32 | AO1: ss_effective_mhz_MIXED | AP1: soak_energy_nJ_row_2to4 | AQ1: soak_energy_nJ_row_2to8 | AR1: soak_energy_nJ_row_2to16 | AS1: soak_energy_nJ_row_2to32 | AT1: soak_energy_nJ_row_MIXED | AU1: ss_gflops_per_W_2to4 | AV1: ss_gflops_per_W_2to8 | AW1: ss_gflops_per_W_2to16 | AX1: ss_gflops_per_W_2to32 | AY1: ss_gflops_per_W_MIXED | AZ1: soak_vccint_W_2to4 | BA1: soak_vccint_W_2to8 | BB1: soak_vccint_W_2to16 | BC1: soak_vccint_W_2to32 | BD1: soak_vccint_W_MIXED | BE1: soak_core_dyn_W_2to4 | BF1: soak_core_dyn_W_2to8 | BG1: soak_core_dyn_W_2to16 | BH1: soak_core_dyn_W_2to32 | BI1: soak_core_dyn_W_MIXED | BJ1: avg3_mrow_s_2to4 | BK1: avg3_mrow_s_2to8 | BL1: avg3_mrow_s_2to16 | BM1: avg3_mrow_s_2to32 | BN1: avg3_mrow_s_MIXED | BO1: avg3_gflops_eff_2to4 | BP1: avg3_gflops_eff_2to8 | BQ1: avg3_gflops_eff_2to16 | BR1: avg3_gflops_eff_2to32 | BS1: avg3_gflops_eff_MIXED | BT1: ss_gmac_act_per_pc_2to4 | BU1: ss_gmac_act_per_pc_2to8 | BV1: ss_gmac_act_per_pc_2to16 | BW1: ss_gmac_act_per_pc_2to32 | BX1: ss_gmac_act_per_pc_MIXED | BY1: ss_gflops_act_per_W_2to4 | BZ1: ss_gflops_act_per_W_2to8 | CA1: ss_gflops_act_per_W_2to16 | CB1: ss_gflops_act_per_W_2to32 | CC1: ss_gflops_act_per_W_MIXED | CD1: ss_bandwidth_GBs_2to4 | CE1: ss_bandwidth_GBs_2to8 | CF1: ss_bandwidth_GBs_2to16 | CG1: ss_bandwidth_GBs_2to32 | CH1: ss_bandwidth_GBs_MIXED | CI1: hbm_input_pcs | CJ1: bandwidth_ceiling_GBs | CK1: gmac_per_pc_theory
A2: 4x4 (T=16) | B2: 4x4 | C2: 4 | D2: 4 | E2: 16 | F2: 128 | G2: 6 | H2: 6 | I2: 32 | J2: 619.6 | K2: 400 | L2: 403.6 | M2: 0.646 | N2: 325.1 | O2: 12.9 | P2: 25.6 | Q2: 27.729 | R2: 27.458 | S2: 27.602 | T2: 27.472 | U2: 27.332 | V2: 50.6 | W2: 101.1 | X2: 200.82 | Y2: 396.41 | Z2: 107.64 | AA2: 25.3 | AB2: 25.28 | AC2: 25.1 | AD2: 24.78 | AE2: 25.23 | AF2: 98.83 | AG2: 98.73 | AH2: 98.06 | AI2: 96.78 | AJ2: 98.55 | AK2: 395.3 | AL2: 394.9 | AM2: 392.2 | AN2: 387.1 | AO2: 394.2 | AP2: 1163.03 | AQ2: 577.26 | AR2: 291.78 | AS2: 147.59 | AT2: 541.53 | AU2: 1.82 | AV2: 3.68 | AW2: 7.28 | AX2: 14.43 | AY2: 3.94 | AZ2: 6.42 | BA2: 6.425 | BB2: 6.355 | BC2: 6.293 | BD2: 6.239 | BE2: 0.284 | BF2: 0.314 | BG2: 0.334 | BH2: 0.295 | BI2: 0.265 | BJ2: 23.194 | BK2: 46.427 | BL2: 91.71 | BM2: 181.351 | BN2: 49.426 | BO2: 47.5 | BP2: 95.08 | BQ2: 187.82 | BR2: 371.41 | BS2: 101.22 | BT2: 2.108 | BU2: 2.106 | BV2: 2.092 | BW2: 2.065 | BX2: 2.102 | BY2: 0.912 | BZ2: 0.921 | CA2: 0.909 | CB2: 0.902 | CC2: 0.923 | CD2: 37.95 | CE2: 37.91 | CF2: 37.65 | CG2: 37.16 | CH2: 37.84 | CI2: 3 | CJ2: 38.4 | CK2: 2.133
A3: 8x4 (T=32) | B3: 8x4 | C3: 8 | D3: 4 | E3: 32 | F3: 256 | G3: 10 | H3: 10 | I3: 64 | J3: 559.9 | K3: 375 | L3: 383.8 | M3: 0.67 | N3: 518.6 | O3: 10.3 | P3: 48 | Q3: 29.882 | R3: 29.975 | S3: 30.002 | T3: 29.833 | U3: 29.79 | V3: 95.08 | W3: 190.57 | X3: 376.63 | Y3: 746.93 | Z3: 202.35 | AA3: 47.54 | AB3: 47.64 | AC3: 47.08 | AD3: 46.68 | AE3: 47.43 | AF3: 99.04 | AG3: 99.25 | AH3: 98.08 | AI3: 97.26 | AJ3: 98.8 | AK3: 371.4 | AL3: 372.2 | AM3: 367.8 | AN3: 364.7 | AO3: 370.5 | AP3: 678.66 | AQ3: 339.36 | AR3: 172.37 | AS3: 86.76 | AT3: 319.82 | AU3: 3.18 | AV3: 6.36 | AW3: 12.55 | AX3: 25.04 | AY3: 6.79 | AZ3: 6.914 | BA3: 7.131 | BB3: 7.222 | BC3: 7.14 | BD3: 7.051 | BE3: 0.39 | BF3: 0.507 | BG3: 0.626 | BH3: 0.637 | BI3: 0.498 | BJ3: 42.678 | BK3: 84.864 | BL3: 168.419 | BM3: 331.859 | BN3: 89.981 | BO3: 87.41 | BP3: 173.8 | BQ3: 344.92 | BR3: 679.65 | BS3: 184.28 | BT3: 2.377 | BU3: 2.382 | BV3: 2.354 | BW3: 2.334 | BX3: 2.371 | BY3: 1.591 | BZ3: 1.589 | CA3: 1.569 | CB3: 1.565 | CC3: 1.592 | CD3: 71.31 | CE3: 71.46 | CF3: 70.62 | CG3: 70.02 | CH3: 71.14 | CI3: 6 | CJ3: 72 | CK3: 2.4
